Error: That port is already in use.
Error: That port is already in use.
/home/pi/www/simHome/simone/home/management/commands/light.py:9: RuntimeWarning: This channel is already in use, continuing anyway.  Use GPIO.setwarnings(False) to disable warnings.
  GPIO.setup(4,GPIO.OUT)
Internal Server Error: /submit/1
Traceback (most recent call last):
  File "/usr/local/lib/python2.7/dist-packages/django/core/handlers/exception.py", line 41, in inner
    response = get_response(request)
  File "/usr/local/lib/python2.7/dist-packages/django/core/handlers/base.py", line 198, in _get_response
    "returned None instead." % (callback.__module__, view_name)
ValueError: The view home.views.submit1 didn't return an HttpResponse object. It returned None instead.
[28/Sep/2017 11:57:52] "GET /submit/1 HTTP/1.1" 500 55687
Traceback (most recent call last):
  File "/usr/lib/python2.7/wsgiref/handlers.py", line 86, in run
    self.finish_response()
  File "/usr/lib/python2.7/wsgiref/handlers.py", line 128, in finish_response
    self.write(data)
  File "/usr/lib/python2.7/wsgiref/handlers.py", line 217, in write
    self._write(data)
  File "/usr/lib/python2.7/socket.py", line 324, in write
    self.flush()
  File "/usr/lib/python2.7/socket.py", line 303, in flush
    self._sock.sendall(view[write_offset:write_offset+buffer_size])
error: [Errno 104] Connection reset by peer
[28/Sep/2017 11:57:52] "GET /submit/1 HTTP/1.1" 500 59
[2017-09-28 11:57:52,807] - Broken pipe from ('192.168.10.51', 35238)

Internal Server Error: /submit/1
Traceback (most recent call last):
  File "/usr/local/lib/python2.7/dist-packages/django/core/handlers/exception.py", line 41, in inner
    response = get_response(request)
  File "/usr/local/lib/python2.7/dist-packages/django/core/handlers/base.py", line 198, in _get_response
    "returned None instead." % (callback.__module__, view_name)
ValueError: The view home.views.submit1 didn't return an HttpResponse object. It returned None instead.
[28/Sep/2017 11:57:53] "GET /submit/1 HTTP/1.1" 500 55687
Traceback (most recent call last):
  File "/usr/lib/python2.7/wsgiref/handlers.py", line 86, in run
    self.finish_response()
  File "/usr/lib/python2.7/wsgiref/handlers.py", line 128, in finish_response
    self.write(data)
  File "/usr/lib/python2.7/wsgiref/handlers.py", line 217, in write
    self._write(data)
  File "/usr/lib/python2.7/socket.py", line 324, in write
    self.flush()
  File "/usr/lib/python2.7/socket.py", line 303, in flush
    self._sock.sendall(view[write_offset:write_offset+buffer_size])
error: [Errno 104] Connection reset by peer
[28/Sep/2017 11:57:53] "GET /submit/1 HTTP/1.1" 500 59
[2017-09-28 11:57:53,838] - Broken pipe from ('192.168.10.51', 35240)

/home/pi/www/simHome/simone/home/management/commands/light2.py:9: RuntimeWarning: This channel is already in use, continuing anyway.  Use GPIO.setwarnings(False) to disable warnings.
  GPIO.setup(17,GPIO.OUT)
Internal Server Error: /submit/2
Traceback (most recent call last):
  File "/usr/local/lib/python2.7/dist-packages/django/core/handlers/exception.py", line 41, in inner
    response = get_response(request)
  File "/usr/local/lib/python2.7/dist-packages/django/core/handlers/base.py", line 198, in _get_response
    "returned None instead." % (callback.__module__, view_name)
ValueError: The view home.views.submit2 didn't return an HttpResponse object. It returned None instead.
[28/Sep/2017 11:57:55] "GET /submit/2 HTTP/1.1" 500 55687
Traceback (most recent call last):
  File "/usr/lib/python2.7/wsgiref/handlers.py", line 86, in run
    self.finish_response()
  File "/usr/lib/python2.7/wsgiref/handlers.py", line 128, in finish_response
    self.write(data)
  File "/usr/lib/python2.7/wsgiref/handlers.py", line 217, in write
    self._write(data)
  File "/usr/lib/python2.7/socket.py", line 324, in write
    self.flush()
  File "/usr/lib/python2.7/socket.py", line 303, in flush
    self._sock.sendall(view[write_offset:write_offset+buffer_size])
error: [Errno 104] Connection reset by peer
[28/Sep/2017 11:57:55] "GET /submit/2 HTTP/1.1" 500 59
[2017-09-28 11:57:55,809] - Broken pipe from ('192.168.10.51', 35242)

Internal Server Error: /submit/2
Traceback (most recent call last):
  File "/usr/local/lib/python2.7/dist-packages/django/core/handlers/exception.py", line 41, in inner
    response = get_response(request)
  File "/usr/local/lib/python2.7/dist-packages/django/core/handlers/base.py", line 198, in _get_response
    "returned None instead." % (callback.__module__, view_name)
ValueError: The view home.views.submit2 didn't return an HttpResponse object. It returned None instead.
[28/Sep/2017 11:57:58] "GET /submit/2 HTTP/1.1" 500 55687
Traceback (most recent call last):
  File "/usr/lib/python2.7/wsgiref/handlers.py", line 86, in run
    self.finish_response()
  File "/usr/lib/python2.7/wsgiref/handlers.py", line 128, in finish_response
    self.write(data)
  File "/usr/lib/python2.7/wsgiref/handlers.py", line 217, in write
    self._write(data)
  File "/usr/lib/python2.7/socket.py", line 324, in write
    self.flush()
  File "/usr/lib/python2.7/socket.py", line 303, in flush
    self._sock.sendall(view[write_offset:write_offset+buffer_size])
error: [Errno 104] Connection reset by peer
[28/Sep/2017 11:57:58] "GET /submit/2 HTTP/1.1" 500 59
[2017-09-28 11:57:58,337] - Broken pipe from ('192.168.10.51', 35244)

sudo: pyhton: command not found
Internal Server Error: /submit/1
Traceback (most recent call last):
  File "/usr/local/lib/python2.7/dist-packages/django/core/handlers/exception.py", line 41, in inner
    response = get_response(request)
  File "/usr/local/lib/python2.7/dist-packages/django/core/handlers/base.py", line 198, in _get_response
    "returned None instead." % (callback.__module__, view_name)
ValueError: The view home.views.submit1 didn't return an HttpResponse object. It returned None instead.
[28/Sep/2017 12:00:33] "GET /submit/1 HTTP/1.1" 500 55687
Traceback (most recent call last):
  File "/usr/lib/python2.7/wsgiref/handlers.py", line 86, in run
    self.finish_response()
  File "/usr/lib/python2.7/wsgiref/handlers.py", line 128, in finish_response
    self.write(data)
  File "/usr/lib/python2.7/wsgiref/handlers.py", line 217, in write
    self._write(data)
  File "/usr/lib/python2.7/socket.py", line 324, in write
    self.flush()
  File "/usr/lib/python2.7/socket.py", line 303, in flush
    self._sock.sendall(view[write_offset:write_offset+buffer_size])
error: [Errno 104] Connection reset by peer
[28/Sep/2017 12:00:33] "GET /submit/1 HTTP/1.1" 500 59
[2017-09-28 12:00:33,591] - Broken pipe from ('192.168.10.51', 35296)

Internal Server Error: /submit/1
Traceback (most recent call last):
  File "/usr/local/lib/python2.7/dist-packages/django/core/handlers/exception.py", line 41, in inner
    response = get_response(request)
  File "/usr/local/lib/python2.7/dist-packages/django/core/handlers/base.py", line 198, in _get_response
    "returned None instead." % (callback.__module__, view_name)
ValueError: The view home.views.submit1 didn't return an HttpResponse object. It returned None instead.
[28/Sep/2017 12:00:35] "GET /submit/1 HTTP/1.1" 500 55687
Traceback (most recent call last):
  File "/usr/lib/python2.7/wsgiref/handlers.py", line 86, in run
    self.finish_response()
  File "/usr/lib/python2.7/wsgiref/handlers.py", line 128, in finish_response
    self.write(data)
  File "/usr/lib/python2.7/wsgiref/handlers.py", line 217, in write
    self._write(data)
  File "/usr/lib/python2.7/socket.py", line 324, in write
    self.flush()
  File "/usr/lib/python2.7/socket.py", line 303, in flush
    self._sock.sendall(view[write_offset:write_offset+buffer_size])
error: [Errno 104] Connection reset by peer
[28/Sep/2017 12:00:35] "GET /submit/1 HTTP/1.1" 500 59
[2017-09-28 12:00:35,838] - Broken pipe from ('192.168.10.51', 35298)

Internal Server Error: /submit/2
Traceback (most recent call last):
  File "/usr/local/lib/python2.7/dist-packages/django/core/handlers/exception.py", line 41, in inner
    response = get_response(request)
  File "/usr/local/lib/python2.7/dist-packages/django/core/handlers/base.py", line 198, in _get_response
    "returned None instead." % (callback.__module__, view_name)
ValueError: The view home.views.submit2 didn't return an HttpResponse object. It returned None instead.
[28/Sep/2017 12:00:37] "GET /submit/2 HTTP/1.1" 500 55687
Traceback (most recent call last):
  File "/usr/lib/python2.7/wsgiref/handlers.py", line 86, in run
    self.finish_response()
  File "/usr/lib/python2.7/wsgiref/handlers.py", line 128, in finish_response
    self.write(data)
  File "/usr/lib/python2.7/wsgiref/handlers.py", line 217, in write
    self._write(data)
  File "/usr/lib/python2.7/socket.py", line 324, in write
    self.flush()
  File "/usr/lib/python2.7/socket.py", line 303, in flush
    self._sock.sendall(view[write_offset:write_offset+buffer_size])
error: [Errno 104] Connection reset by peer
[28/Sep/2017 12:00:37] "GET /submit/2 HTTP/1.1" 500 59
[2017-09-28 12:00:37,122] - Broken pipe from ('192.168.10.51', 35300)

Internal Server Error: /submit/2
Traceback (most recent call last):
  File "/usr/local/lib/python2.7/dist-packages/django/core/handlers/exception.py", line 41, in inner
    response = get_response(request)
  File "/usr/local/lib/python2.7/dist-packages/django/core/handlers/base.py", line 198, in _get_response
    "returned None instead." % (callback.__module__, view_name)
ValueError: The view home.views.submit2 didn't return an HttpResponse object. It returned None instead.
[28/Sep/2017 12:00:38] "GET /submit/2 HTTP/1.1" 500 55687
Traceback (most recent call last):
  File "/usr/lib/python2.7/wsgiref/handlers.py", line 86, in run
    self.finish_response()
  File "/usr/lib/python2.7/wsgiref/handlers.py", line 128, in finish_response
    self.write(data)
  File "/usr/lib/python2.7/wsgiref/handlers.py", line 217, in write
    self._write(data)
  File "/usr/lib/python2.7/socket.py", line 324, in write
    self.flush()
  File "/usr/lib/python2.7/socket.py", line 303, in flush
    self._sock.sendall(view[write_offset:write_offset+buffer_size])
error: [Errno 104] Connection reset by peer
[28/Sep/2017 12:00:38] "GET /submit/2 HTTP/1.1" 500 59
[2017-09-28 12:00:38,721] - Broken pipe from ('192.168.10.51', 35302)

sudo: pyhton: command not found
sudo: pyhton: command not found
